INFO     celery.worker.consumer.connection:connection.py:22 Connected to memory://localhost//
INFO     celery.app.trace:trace.py:128 Task celery.ping[431acdb9-8a2f-4ed8-a0ce-9bc0eb733a2d] succeeded in 0.04901543600001901s: 'pong'
INFO     httpx:_client.py:1025 HTTP Request: POST http://testserver/api/words "HTTP/1.1 303 See Other"
INFO     root:client.py:77 ->> POST /api/words
INFO     root:client.py:83 Query params: None
INFO     root:client.py:86 Request body: None
INFO     root:client.py:88 <<- 303
INFO     root:client.py:91 None
INFO     httpx:_client.py:1025 HTTP Request: GET http://testserver/api/words/8861f6bc-ea04-4297-879d-9e7ae4c41a5d "HTTP/1.1 202 Accepted"
INFO     root:client.py:77 ->> GET /api/words/8861f6bc-ea04-4297-879d-9e7ae4c41a5d
INFO     root:client.py:83 Query params: None
INFO     root:client.py:88 <<- 202
INFO     root:client.py:94 
INFO     httpx:_client.py:1025 HTTP Request: GET http://testserver/api/words/8861f6bc-ea04-4297-879d-9e7ae4c41a5d "HTTP/1.1 202 Accepted"
INFO     root:client.py:77 ->> GET /api/words/8861f6bc-ea04-4297-879d-9e7ae4c41a5d
INFO     root:client.py:83 Query params: None
INFO     root:client.py:88 <<- 202
INFO     root:client.py:94 
INFO     celery.worker.strategy:strategy.py:161 Task tasks.words[8861f6bc-ea04-4297-879d-9e7ae4c41a5d] received
INFO     celery.app.trace:trace.py:128 Task tasks.words[8861f6bc-ea04-4297-879d-9e7ae4c41a5d] succeeded in 0.03244424100000742s: 69
INFO     httpx:_client.py:1025 HTTP Request: GET http://testserver/api/words/8861f6bc-ea04-4297-879d-9e7ae4c41a5d "HTTP/1.1 200 OK"
INFO     root:client.py:77 ->> GET /api/words/8861f6bc-ea04-4297-879d-9e7ae4c41a5d
INFO     root:client.py:83 Query params: None
INFO     root:client.py:88 <<- 200
INFO     root:client.py:91 {'count': 69}