INFO     celery.worker.consumer.connection:connection.py:22 Connected to memory://localhost//
INFO     celery.app.trace:trace.py:128 Task celery.ping[f7821121-53e8-4d31-9bdf-7037a4f45b8e] succeeded in 0.03175375799997937s: 'pong'
INFO     httpx:_client.py:1025 HTTP Request: POST http://testserver/api/words "HTTP/1.1 303 See Other"
INFO     root:client.py:77 ->> POST /api/words
INFO     root:client.py:83 Query params: None
INFO     root:client.py:86 Request body: None
INFO     root:client.py:88 <<- 303
INFO     root:client.py:91 None
INFO     httpx:_client.py:1025 HTTP Request: GET http://testserver/api/words/c5bb1f61-5f73-4e53-a5c4-09e6233a98d5 "HTTP/1.1 202 Accepted"
INFO     root:client.py:77 ->> GET /api/words/c5bb1f61-5f73-4e53-a5c4-09e6233a98d5
INFO     root:client.py:83 Query params: None
INFO     root:client.py:88 <<- 202
INFO     root:client.py:94 
INFO     httpx:_client.py:1025 HTTP Request: GET http://testserver/api/words/c5bb1f61-5f73-4e53-a5c4-09e6233a98d5 "HTTP/1.1 202 Accepted"
INFO     root:client.py:77 ->> GET /api/words/c5bb1f61-5f73-4e53-a5c4-09e6233a98d5
INFO     root:client.py:83 Query params: None
INFO     root:client.py:88 <<- 202
INFO     root:client.py:94 
INFO     celery.worker.strategy:strategy.py:161 Task tasks.words[c5bb1f61-5f73-4e53-a5c4-09e6233a98d5] received
INFO     celery.app.trace:trace.py:128 Task tasks.words[c5bb1f61-5f73-4e53-a5c4-09e6233a98d5] succeeded in 0.01130722999999989s: 69
INFO     httpx:_client.py:1025 HTTP Request: GET http://testserver/api/words/c5bb1f61-5f73-4e53-a5c4-09e6233a98d5 "HTTP/1.1 200 OK"
INFO     root:client.py:77 ->> GET /api/words/c5bb1f61-5f73-4e53-a5c4-09e6233a98d5
INFO     root:client.py:83 Query params: None
INFO     root:client.py:88 <<- 200
INFO     root:client.py:91 {'count': 69}