INFO     celery.worker.consumer.connection:connection.py:22 Connected to memory://localhost//
INFO     celery.app.trace:trace.py:128 Task celery.ping[879b4bef-d07b-45f6-be43-5faf0f9e29e7] succeeded in 0.05093165100004171s: 'pong'
INFO     httpx:_client.py:1025 HTTP Request: POST http://testserver/api/words "HTTP/1.1 303 See Other"
INFO     root:client.py:77 ->> POST /api/words
INFO     root:client.py:83 Query params: None
INFO     root:client.py:86 Request body: None
INFO     root:client.py:88 <<- 303
INFO     root:client.py:91 None
INFO     httpx:_client.py:1025 HTTP Request: GET http://testserver/api/words/0cdf1483-b0b8-4940-8d9a-79be6c95a0e9 "HTTP/1.1 202 Accepted"
INFO     root:client.py:77 ->> GET /api/words/0cdf1483-b0b8-4940-8d9a-79be6c95a0e9
INFO     root:client.py:83 Query params: None
INFO     root:client.py:88 <<- 202
INFO     root:client.py:94 
INFO     httpx:_client.py:1025 HTTP Request: GET http://testserver/api/words/0cdf1483-b0b8-4940-8d9a-79be6c95a0e9 "HTTP/1.1 202 Accepted"
INFO     root:client.py:77 ->> GET /api/words/0cdf1483-b0b8-4940-8d9a-79be6c95a0e9
INFO     root:client.py:83 Query params: None
INFO     root:client.py:88 <<- 202
INFO     root:client.py:94 
INFO     celery.worker.strategy:strategy.py:161 Task tasks.words[0cdf1483-b0b8-4940-8d9a-79be6c95a0e9] received
INFO     celery.app.trace:trace.py:128 Task tasks.words[0cdf1483-b0b8-4940-8d9a-79be6c95a0e9] succeeded in 0.02489877499999693s: 69
INFO     httpx:_client.py:1025 HTTP Request: GET http://testserver/api/words/0cdf1483-b0b8-4940-8d9a-79be6c95a0e9 "HTTP/1.1 200 OK"
INFO     root:client.py:77 ->> GET /api/words/0cdf1483-b0b8-4940-8d9a-79be6c95a0e9
INFO     root:client.py:83 Query params: None
INFO     root:client.py:88 <<- 200
INFO     root:client.py:91 {'count': 69}